[2025-01-05T22:52:44.329+0000] {local_task_job_runner.py:123} INFO - ::group::Pre task execution logs
[2025-01-05T22:52:44.341+0000] {taskinstance.py:2613} INFO - Dependencies all met for dep_context=non-requeueable deps ti=<TaskInstance: ico_scraping_dag_09.scrape_ico_data scheduled__2025-01-04T00:00:00+00:00 [queued]>
[2025-01-05T22:52:44.347+0000] {taskinstance.py:2613} INFO - Dependencies all met for dep_context=requeueable deps ti=<TaskInstance: ico_scraping_dag_09.scrape_ico_data scheduled__2025-01-04T00:00:00+00:00 [queued]>
[2025-01-05T22:52:44.347+0000] {taskinstance.py:2866} INFO - Starting attempt 1 of 2
[2025-01-05T22:52:44.357+0000] {taskinstance.py:2889} INFO - Executing <Task(PythonOperator): scrape_ico_data> on 2025-01-04 00:00:00+00:00
[2025-01-05T22:52:44.365+0000] {standard_task_runner.py:104} INFO - Running: ['***', 'tasks', 'run', 'ico_scraping_dag_09', 'scrape_ico_data', 'scheduled__2025-01-04T00:00:00+00:00', '--job-id', '4', '--raw', '--subdir', 'DAGS_FOLDER/selenium_dag_01.py', '--cfg-path', '/tmp/tmppy5xf92m']
[2025-01-05T22:52:44.368+0000] {standard_task_runner.py:105} INFO - Job 4: Subtask scrape_ico_data
[2025-01-05T22:52:44.369+0000] {logging_mixin.py:190} WARNING - /home/***/.local/lib/python3.12/site-packages/***/task/task_runner/standard_task_runner.py:70 DeprecationWarning: This process (pid=257) is multi-threaded, use of fork() may lead to deadlocks in the child.
[2025-01-05T22:52:44.369+0000] {standard_task_runner.py:72} INFO - Started process 259 to run task
[2025-01-05T22:52:44.417+0000] {task_command.py:467} INFO - Running <TaskInstance: ico_scraping_dag_09.scrape_ico_data scheduled__2025-01-04T00:00:00+00:00 [running]> on host fd4b5ca82add
[2025-01-05T22:52:44.481+0000] {taskinstance.py:3132} INFO - Exporting env vars: AIRFLOW_CTX_DAG_OWNER='***' AIRFLOW_CTX_DAG_ID='ico_scraping_dag_09' AIRFLOW_CTX_TASK_ID='scrape_ico_data' AIRFLOW_CTX_EXECUTION_DATE='2025-01-04T00:00:00+00:00' AIRFLOW_CTX_TRY_NUMBER='1' AIRFLOW_CTX_DAG_RUN_ID='scheduled__2025-01-04T00:00:00+00:00'
[2025-01-05T22:52:44.482+0000] {taskinstance.py:731} INFO - ::endgroup::
[2025-01-05T22:52:44.493+0000] {logging_mixin.py:190} INFO - Starting the web scraping process...
[2025-01-05T22:52:44.493+0000] {logging_mixin.py:190} INFO - Chrome binary location set to: /usr/bin/custom-google-chrome
[2025-01-05T22:52:44.494+0000] {logging_mixin.py:190} INFO - ChromeDriver path set to: /opt/chromedriver_linux64/chromedriver
[2025-01-05T22:52:45.635+0000] {taskinstance.py:3311} ERROR - Task failed with exception
Traceback (most recent call last):
  File "/home/airflow/.local/lib/python3.12/site-packages/airflow/models/taskinstance.py", line 767, in _execute_task
    result = _execute_callable(context=context, **execute_callable_kwargs)
             ^^^^^^^^^^^^^^^^^^^^^^^^^^^^^^^^^^^^^^^^^^^^^^^^^^^^^^^^^^^^^
  File "/home/airflow/.local/lib/python3.12/site-packages/airflow/models/taskinstance.py", line 733, in _execute_callable
    return ExecutionCallableRunner(
           ^^^^^^^^^^^^^^^^^^^^^^^^
  File "/home/airflow/.local/lib/python3.12/site-packages/airflow/utils/operator_helpers.py", line 252, in run
    return self.func(*args, **kwargs)
           ^^^^^^^^^^^^^^^^^^^^^^^^^^
  File "/home/airflow/.local/lib/python3.12/site-packages/airflow/models/baseoperator.py", line 422, in wrapper
    return func(self, *args, **kwargs)
           ^^^^^^^^^^^^^^^^^^^^^^^^^^^
  File "/home/airflow/.local/lib/python3.12/site-packages/airflow/operators/python.py", line 238, in execute
    return_value = self.execute_callable()
                   ^^^^^^^^^^^^^^^^^^^^^^^
  File "/home/airflow/.local/lib/python3.12/site-packages/airflow/operators/python.py", line 256, in execute_callable
    return runner.run(*self.op_args, **self.op_kwargs)
           ^^^^^^^^^^^^^^^^^^^^^^^^^^^^^^^^^^^^^^^^^^^
  File "/home/airflow/.local/lib/python3.12/site-packages/airflow/utils/operator_helpers.py", line 252, in run
    return self.func(*args, **kwargs)
           ^^^^^^^^^^^^^^^^^^^^^^^^^^
  File "/opt/airflow/dags/selenium_dag_01.py", line 138, in scrape_data
    driver = webdriver.Chrome(service=service, options=chrome_options)
             ^^^^^^^^^^^^^^^^^^^^^^^^^^^^^^^^^^^^^^^^^^^^^^^^^^^^^^^^^
  File "/home/airflow/.local/lib/python3.12/site-packages/selenium/webdriver/chrome/webdriver.py", line 45, in __init__
    super().__init__(
  File "/home/airflow/.local/lib/python3.12/site-packages/selenium/webdriver/chromium/webdriver.py", line 66, in __init__
    super().__init__(command_executor=executor, options=options)
  File "/home/airflow/.local/lib/python3.12/site-packages/selenium/webdriver/remote/webdriver.py", line 241, in __init__
    self.start_session(capabilities)
  File "/home/airflow/.local/lib/python3.12/site-packages/selenium/webdriver/remote/webdriver.py", line 329, in start_session
    response = self.execute(Command.NEW_SESSION, caps)["value"]
               ^^^^^^^^^^^^^^^^^^^^^^^^^^^^^^^^^^^^^^^
  File "/home/airflow/.local/lib/python3.12/site-packages/selenium/webdriver/remote/webdriver.py", line 384, in execute
    self.error_handler.check_response(response)
  File "/home/airflow/.local/lib/python3.12/site-packages/selenium/webdriver/remote/errorhandler.py", line 232, in check_response
    raise exception_class(message, screen, stacktrace)
selenium.common.exceptions.WebDriverException: Message: unknown error: Chrome failed to start: exited abnormally.
  (chrome not reachable)
  (The process started from chrome location /usr/bin/custom-google-chrome is no longer running, so ChromeDriver is assuming that Chrome has crashed.)
Stacktrace:
#0 0x563f06fdf4e3 <unknown>
#1 0x563f06d0ec76 <unknown>
#2 0x563f06d37d78 <unknown>
#3 0x563f06d34029 <unknown>
#4 0x563f06d72ccc <unknown>
#5 0x563f06d7247f <unknown>
#6 0x563f06d69de3 <unknown>
#7 0x563f06d3f2dd <unknown>
#8 0x563f06d4034e <unknown>
#9 0x563f06f9f3e4 <unknown>
#10 0x563f06fa33d7 <unknown>
#11 0x563f06fadb20 <unknown>
#12 0x563f06fa4023 <unknown>
#13 0x563f06f721aa <unknown>
#14 0x563f06fc86b8 <unknown>
#15 0x563f06fc8847 <unknown>
#16 0x563f06fd8243 <unknown>
#17 0x7fb987adf1c4 <unknown>

[2025-01-05T22:52:45.647+0000] {taskinstance.py:1225} INFO - Marking task as UP_FOR_RETRY. dag_id=ico_scraping_dag_09, task_id=scrape_ico_data, run_id=scheduled__2025-01-04T00:00:00+00:00, execution_date=20250104T000000, start_date=20250105T225244, end_date=20250105T225245
[2025-01-05T22:52:45.660+0000] {taskinstance.py:340} INFO - ::group::Post task execution logs
[2025-01-05T22:52:45.660+0000] {standard_task_runner.py:124} ERROR - Failed to execute job 4 for task scrape_ico_data (Message: unknown error: Chrome failed to start: exited abnormally.
  (chrome not reachable)
  (The process started from chrome location /usr/bin/custom-google-chrome is no longer running, so ChromeDriver is assuming that Chrome has crashed.)
Stacktrace:
#0 0x563f06fdf4e3 <unknown>
#1 0x563f06d0ec76 <unknown>
#2 0x563f06d37d78 <unknown>
#3 0x563f06d34029 <unknown>
#4 0x563f06d72ccc <unknown>
#5 0x563f06d7247f <unknown>
#6 0x563f06d69de3 <unknown>
#7 0x563f06d3f2dd <unknown>
#8 0x563f06d4034e <unknown>
#9 0x563f06f9f3e4 <unknown>
#10 0x563f06fa33d7 <unknown>
#11 0x563f06fadb20 <unknown>
#12 0x563f06fa4023 <unknown>
#13 0x563f06f721aa <unknown>
#14 0x563f06fc86b8 <unknown>
#15 0x563f06fc8847 <unknown>
#16 0x563f06fd8243 <unknown>
#17 0x7fb987adf1c4 <unknown>
; 259)
Traceback (most recent call last):
  File "/home/airflow/.local/lib/python3.12/site-packages/airflow/task/task_runner/standard_task_runner.py", line 117, in _start_by_fork
    ret = args.func(args, dag=self.dag)
          ^^^^^^^^^^^^^^^^^^^^^^^^^^^^^
  File "/home/airflow/.local/lib/python3.12/site-packages/airflow/cli/cli_config.py", line 49, in command
    return func(*args, **kwargs)
           ^^^^^^^^^^^^^^^^^^^^^
  File "/home/airflow/.local/lib/python3.12/site-packages/airflow/utils/cli.py", line 116, in wrapper
    return f(*args, **kwargs)
           ^^^^^^^^^^^^^^^^^^
  File "/home/airflow/.local/lib/python3.12/site-packages/airflow/cli/commands/task_command.py", line 483, in task_run
    task_return_code = _run_task_by_selected_method(args, _dag, ti)
                       ^^^^^^^^^^^^^^^^^^^^^^^^^^^^^^^^^^^^^^^^^^^^
  File "/home/airflow/.local/lib/python3.12/site-packages/airflow/cli/commands/task_command.py", line 256, in _run_task_by_selected_method
    return _run_raw_task(args, ti)
           ^^^^^^^^^^^^^^^^^^^^^^^
  File "/home/airflow/.local/lib/python3.12/site-packages/airflow/cli/commands/task_command.py", line 341, in _run_raw_task
    return ti._run_raw_task(
           ^^^^^^^^^^^^^^^^^
  File "/home/airflow/.local/lib/python3.12/site-packages/airflow/utils/session.py", line 97, in wrapper
    return func(*args, session=session, **kwargs)
           ^^^^^^^^^^^^^^^^^^^^^^^^^^^^^^^^^^^^^^
  File "/home/airflow/.local/lib/python3.12/site-packages/airflow/models/taskinstance.py", line 3005, in _run_raw_task
    return _run_raw_task(
           ^^^^^^^^^^^^^^
  File "/home/airflow/.local/lib/python3.12/site-packages/airflow/models/taskinstance.py", line 273, in _run_raw_task
    TaskInstance._execute_task_with_callbacks(
  File "/home/airflow/.local/lib/python3.12/site-packages/airflow/models/taskinstance.py", line 3159, in _execute_task_with_callbacks
    result = self._execute_task(context, task_orig)
             ^^^^^^^^^^^^^^^^^^^^^^^^^^^^^^^^^^^^^^
  File "/home/airflow/.local/lib/python3.12/site-packages/airflow/models/taskinstance.py", line 3183, in _execute_task
    return _execute_task(self, context, task_orig)
           ^^^^^^^^^^^^^^^^^^^^^^^^^^^^^^^^^^^^^^^
  File "/home/airflow/.local/lib/python3.12/site-packages/airflow/models/taskinstance.py", line 767, in _execute_task
    result = _execute_callable(context=context, **execute_callable_kwargs)
             ^^^^^^^^^^^^^^^^^^^^^^^^^^^^^^^^^^^^^^^^^^^^^^^^^^^^^^^^^^^^^
  File "/home/airflow/.local/lib/python3.12/site-packages/airflow/models/taskinstance.py", line 733, in _execute_callable
    return ExecutionCallableRunner(
           ^^^^^^^^^^^^^^^^^^^^^^^^
  File "/home/airflow/.local/lib/python3.12/site-packages/airflow/utils/operator_helpers.py", line 252, in run
    return self.func(*args, **kwargs)
           ^^^^^^^^^^^^^^^^^^^^^^^^^^
  File "/home/airflow/.local/lib/python3.12/site-packages/airflow/models/baseoperator.py", line 422, in wrapper
    return func(self, *args, **kwargs)
           ^^^^^^^^^^^^^^^^^^^^^^^^^^^
  File "/home/airflow/.local/lib/python3.12/site-packages/airflow/operators/python.py", line 238, in execute
    return_value = self.execute_callable()
                   ^^^^^^^^^^^^^^^^^^^^^^^
  File "/home/airflow/.local/lib/python3.12/site-packages/airflow/operators/python.py", line 256, in execute_callable
    return runner.run(*self.op_args, **self.op_kwargs)
           ^^^^^^^^^^^^^^^^^^^^^^^^^^^^^^^^^^^^^^^^^^^
  File "/home/airflow/.local/lib/python3.12/site-packages/airflow/utils/operator_helpers.py", line 252, in run
    return self.func(*args, **kwargs)
           ^^^^^^^^^^^^^^^^^^^^^^^^^^
  File "/opt/airflow/dags/selenium_dag_01.py", line 138, in scrape_data
    driver = webdriver.Chrome(service=service, options=chrome_options)
             ^^^^^^^^^^^^^^^^^^^^^^^^^^^^^^^^^^^^^^^^^^^^^^^^^^^^^^^^^
  File "/home/airflow/.local/lib/python3.12/site-packages/selenium/webdriver/chrome/webdriver.py", line 45, in __init__
    super().__init__(
  File "/home/airflow/.local/lib/python3.12/site-packages/selenium/webdriver/chromium/webdriver.py", line 66, in __init__
    super().__init__(command_executor=executor, options=options)
  File "/home/airflow/.local/lib/python3.12/site-packages/selenium/webdriver/remote/webdriver.py", line 241, in __init__
    self.start_session(capabilities)
  File "/home/airflow/.local/lib/python3.12/site-packages/selenium/webdriver/remote/webdriver.py", line 329, in start_session
    response = self.execute(Command.NEW_SESSION, caps)["value"]
               ^^^^^^^^^^^^^^^^^^^^^^^^^^^^^^^^^^^^^^^
  File "/home/airflow/.local/lib/python3.12/site-packages/selenium/webdriver/remote/webdriver.py", line 384, in execute
    self.error_handler.check_response(response)
  File "/home/airflow/.local/lib/python3.12/site-packages/selenium/webdriver/remote/errorhandler.py", line 232, in check_response
    raise exception_class(message, screen, stacktrace)
selenium.common.exceptions.WebDriverException: Message: unknown error: Chrome failed to start: exited abnormally.
  (chrome not reachable)
  (The process started from chrome location /usr/bin/custom-google-chrome is no longer running, so ChromeDriver is assuming that Chrome has crashed.)
Stacktrace:
#0 0x563f06fdf4e3 <unknown>
#1 0x563f06d0ec76 <unknown>
#2 0x563f06d37d78 <unknown>
#3 0x563f06d34029 <unknown>
#4 0x563f06d72ccc <unknown>
#5 0x563f06d7247f <unknown>
#6 0x563f06d69de3 <unknown>
#7 0x563f06d3f2dd <unknown>
#8 0x563f06d4034e <unknown>
#9 0x563f06f9f3e4 <unknown>
#10 0x563f06fa33d7 <unknown>
#11 0x563f06fadb20 <unknown>
#12 0x563f06fa4023 <unknown>
#13 0x563f06f721aa <unknown>
#14 0x563f06fc86b8 <unknown>
#15 0x563f06fc8847 <unknown>
#16 0x563f06fd8243 <unknown>
#17 0x7fb987adf1c4 <unknown>

[2025-01-05T22:52:45.669+0000] {local_task_job_runner.py:266} INFO - Task exited with return code 1
[2025-01-05T22:52:45.684+0000] {taskinstance.py:3895} INFO - 0 downstream tasks scheduled from follow-on schedule check
[2025-01-05T22:52:45.686+0000] {local_task_job_runner.py:245} INFO - ::endgroup::
