[2025-01-05T22:40:56.492+0000] {local_task_job_runner.py:123} INFO - ::group::Pre task execution logs
[2025-01-05T22:40:56.508+0000] {taskinstance.py:2613} INFO - Dependencies all met for dep_context=non-requeueable deps ti=<TaskInstance: ico_scraping_dag_08.scrape_ico_data scheduled__2025-01-04T00:00:00+00:00 [queued]>
[2025-01-05T22:40:56.518+0000] {taskinstance.py:2613} INFO - Dependencies all met for dep_context=requeueable deps ti=<TaskInstance: ico_scraping_dag_08.scrape_ico_data scheduled__2025-01-04T00:00:00+00:00 [queued]>
[2025-01-05T22:40:56.518+0000] {taskinstance.py:2866} INFO - Starting attempt 3 of 4
[2025-01-05T22:40:56.531+0000] {taskinstance.py:2889} INFO - Executing <Task(PythonOperator): scrape_ico_data> on 2025-01-04 00:00:00+00:00
[2025-01-05T22:40:56.539+0000] {standard_task_runner.py:104} INFO - Running: ['***', 'tasks', 'run', 'ico_scraping_dag_08', 'scrape_ico_data', 'scheduled__2025-01-04T00:00:00+00:00', '--job-id', '5', '--raw', '--subdir', 'DAGS_FOLDER/selenium_dag_01.py', '--cfg-path', '/tmp/tmpgfv48c0x']
[2025-01-05T22:40:56.543+0000] {standard_task_runner.py:105} INFO - Job 5: Subtask scrape_ico_data
[2025-01-05T22:40:56.547+0000] {logging_mixin.py:190} WARNING - /home/***/.local/lib/python3.12/site-packages/***/task/task_runner/standard_task_runner.py:70 DeprecationWarning: This process (pid=335) is multi-threaded, use of fork() may lead to deadlocks in the child.
[2025-01-05T22:40:56.548+0000] {standard_task_runner.py:72} INFO - Started process 337 to run task
[2025-01-05T22:40:56.601+0000] {task_command.py:467} INFO - Running <TaskInstance: ico_scraping_dag_08.scrape_ico_data scheduled__2025-01-04T00:00:00+00:00 [running]> on host 73a74995ae0f
[2025-01-05T22:40:56.675+0000] {taskinstance.py:3132} INFO - Exporting env vars: AIRFLOW_CTX_DAG_OWNER='***' AIRFLOW_CTX_DAG_ID='ico_scraping_dag_08' AIRFLOW_CTX_TASK_ID='scrape_ico_data' AIRFLOW_CTX_EXECUTION_DATE='2025-01-04T00:00:00+00:00' AIRFLOW_CTX_TRY_NUMBER='3' AIRFLOW_CTX_DAG_RUN_ID='scheduled__2025-01-04T00:00:00+00:00'
[2025-01-05T22:40:56.676+0000] {taskinstance.py:731} INFO - ::endgroup::
[2025-01-05T22:40:56.689+0000] {logging_mixin.py:190} INFO - Starting the web scraping process...
[2025-01-05T22:40:56.689+0000] {logging_mixin.py:190} INFO - Chrome binary location set to: /usr/bin/custom-google-chrome
[2025-01-05T22:40:56.690+0000] {logging_mixin.py:190} INFO - ChromeDriver path set to: /opt/chromedriver_linux64/chromedriver
[2025-01-05T22:40:56.747+0000] {taskinstance.py:3311} ERROR - Task failed with exception
Traceback (most recent call last):
  File "/home/airflow/.local/lib/python3.12/site-packages/airflow/models/taskinstance.py", line 767, in _execute_task
    result = _execute_callable(context=context, **execute_callable_kwargs)
             ^^^^^^^^^^^^^^^^^^^^^^^^^^^^^^^^^^^^^^^^^^^^^^^^^^^^^^^^^^^^^
  File "/home/airflow/.local/lib/python3.12/site-packages/airflow/models/taskinstance.py", line 733, in _execute_callable
    return ExecutionCallableRunner(
           ^^^^^^^^^^^^^^^^^^^^^^^^
  File "/home/airflow/.local/lib/python3.12/site-packages/airflow/utils/operator_helpers.py", line 252, in run
    return self.func(*args, **kwargs)
           ^^^^^^^^^^^^^^^^^^^^^^^^^^
  File "/home/airflow/.local/lib/python3.12/site-packages/airflow/models/baseoperator.py", line 422, in wrapper
    return func(self, *args, **kwargs)
           ^^^^^^^^^^^^^^^^^^^^^^^^^^^
  File "/home/airflow/.local/lib/python3.12/site-packages/airflow/operators/python.py", line 238, in execute
    return_value = self.execute_callable()
                   ^^^^^^^^^^^^^^^^^^^^^^^
  File "/home/airflow/.local/lib/python3.12/site-packages/airflow/operators/python.py", line 256, in execute_callable
    return runner.run(*self.op_args, **self.op_kwargs)
           ^^^^^^^^^^^^^^^^^^^^^^^^^^^^^^^^^^^^^^^^^^^
  File "/home/airflow/.local/lib/python3.12/site-packages/airflow/utils/operator_helpers.py", line 252, in run
    return self.func(*args, **kwargs)
           ^^^^^^^^^^^^^^^^^^^^^^^^^^
  File "/opt/airflow/dags/selenium_dag_01.py", line 137, in scrape_data
    driver = webdriver.Chrome(service=service, options=chrome_options)
             ^^^^^^^^^^^^^^^^^^^^^^^^^^^^^^^^^^^^^^^^^^^^^^^^^^^^^^^^^
  File "/home/airflow/.local/lib/python3.12/site-packages/selenium/webdriver/chrome/webdriver.py", line 45, in __init__
    super().__init__(
  File "/home/airflow/.local/lib/python3.12/site-packages/selenium/webdriver/chromium/webdriver.py", line 66, in __init__
    super().__init__(command_executor=executor, options=options)
  File "/home/airflow/.local/lib/python3.12/site-packages/selenium/webdriver/remote/webdriver.py", line 241, in __init__
    self.start_session(capabilities)
  File "/home/airflow/.local/lib/python3.12/site-packages/selenium/webdriver/remote/webdriver.py", line 329, in start_session
    response = self.execute(Command.NEW_SESSION, caps)["value"]
               ^^^^^^^^^^^^^^^^^^^^^^^^^^^^^^^^^^^^^^^
  File "/home/airflow/.local/lib/python3.12/site-packages/selenium/webdriver/remote/webdriver.py", line 384, in execute
    self.error_handler.check_response(response)
  File "/home/airflow/.local/lib/python3.12/site-packages/selenium/webdriver/remote/errorhandler.py", line 232, in check_response
    raise exception_class(message, screen, stacktrace)
selenium.common.exceptions.WebDriverException: Message: unknown error: Chrome failed to start: exited abnormally.
  (unknown error: DevToolsActivePort file doesn't exist)
  (The process started from chrome location /usr/bin/custom-google-chrome is no longer running, so ChromeDriver is assuming that Chrome has crashed.)
Stacktrace:
#0 0x5620b742e4e3 <unknown>
#1 0x5620b715dc76 <unknown>
#2 0x5620b7186d78 <unknown>
#3 0x5620b7183029 <unknown>
#4 0x5620b71c1ccc <unknown>
#5 0x5620b71c147f <unknown>
#6 0x5620b71b8de3 <unknown>
#7 0x5620b718e2dd <unknown>
#8 0x5620b718f34e <unknown>
#9 0x5620b73ee3e4 <unknown>
#10 0x5620b73f23d7 <unknown>
#11 0x5620b73fcb20 <unknown>
#12 0x5620b73f3023 <unknown>
#13 0x5620b73c11aa <unknown>
#14 0x5620b74176b8 <unknown>
#15 0x5620b7417847 <unknown>
#16 0x5620b7427243 <unknown>
#17 0x7f83f819e1c4 <unknown>

[2025-01-05T22:40:56.759+0000] {taskinstance.py:1225} INFO - Marking task as UP_FOR_RETRY. dag_id=ico_scraping_dag_08, task_id=scrape_ico_data, run_id=scheduled__2025-01-04T00:00:00+00:00, execution_date=20250104T000000, start_date=20250105T224056, end_date=20250105T224056
[2025-01-05T22:40:56.772+0000] {taskinstance.py:340} INFO - ::group::Post task execution logs
[2025-01-05T22:40:56.772+0000] {standard_task_runner.py:124} ERROR - Failed to execute job 5 for task scrape_ico_data (Message: unknown error: Chrome failed to start: exited abnormally.
  (unknown error: DevToolsActivePort file doesn't exist)
  (The process started from chrome location /usr/bin/custom-google-chrome is no longer running, so ChromeDriver is assuming that Chrome has crashed.)
Stacktrace:
#0 0x5620b742e4e3 <unknown>
#1 0x5620b715dc76 <unknown>
#2 0x5620b7186d78 <unknown>
#3 0x5620b7183029 <unknown>
#4 0x5620b71c1ccc <unknown>
#5 0x5620b71c147f <unknown>
#6 0x5620b71b8de3 <unknown>
#7 0x5620b718e2dd <unknown>
#8 0x5620b718f34e <unknown>
#9 0x5620b73ee3e4 <unknown>
#10 0x5620b73f23d7 <unknown>
#11 0x5620b73fcb20 <unknown>
#12 0x5620b73f3023 <unknown>
#13 0x5620b73c11aa <unknown>
#14 0x5620b74176b8 <unknown>
#15 0x5620b7417847 <unknown>
#16 0x5620b7427243 <unknown>
#17 0x7f83f819e1c4 <unknown>
; 337)
Traceback (most recent call last):
  File "/home/airflow/.local/lib/python3.12/site-packages/airflow/task/task_runner/standard_task_runner.py", line 117, in _start_by_fork
    ret = args.func(args, dag=self.dag)
          ^^^^^^^^^^^^^^^^^^^^^^^^^^^^^
  File "/home/airflow/.local/lib/python3.12/site-packages/airflow/cli/cli_config.py", line 49, in command
    return func(*args, **kwargs)
           ^^^^^^^^^^^^^^^^^^^^^
  File "/home/airflow/.local/lib/python3.12/site-packages/airflow/utils/cli.py", line 116, in wrapper
    return f(*args, **kwargs)
           ^^^^^^^^^^^^^^^^^^
  File "/home/airflow/.local/lib/python3.12/site-packages/airflow/cli/commands/task_command.py", line 483, in task_run
    task_return_code = _run_task_by_selected_method(args, _dag, ti)
                       ^^^^^^^^^^^^^^^^^^^^^^^^^^^^^^^^^^^^^^^^^^^^
  File "/home/airflow/.local/lib/python3.12/site-packages/airflow/cli/commands/task_command.py", line 256, in _run_task_by_selected_method
    return _run_raw_task(args, ti)
           ^^^^^^^^^^^^^^^^^^^^^^^
  File "/home/airflow/.local/lib/python3.12/site-packages/airflow/cli/commands/task_command.py", line 341, in _run_raw_task
    return ti._run_raw_task(
           ^^^^^^^^^^^^^^^^^
  File "/home/airflow/.local/lib/python3.12/site-packages/airflow/utils/session.py", line 97, in wrapper
    return func(*args, session=session, **kwargs)
           ^^^^^^^^^^^^^^^^^^^^^^^^^^^^^^^^^^^^^^
  File "/home/airflow/.local/lib/python3.12/site-packages/airflow/models/taskinstance.py", line 3005, in _run_raw_task
    return _run_raw_task(
           ^^^^^^^^^^^^^^
  File "/home/airflow/.local/lib/python3.12/site-packages/airflow/models/taskinstance.py", line 273, in _run_raw_task
    TaskInstance._execute_task_with_callbacks(
  File "/home/airflow/.local/lib/python3.12/site-packages/airflow/models/taskinstance.py", line 3159, in _execute_task_with_callbacks
    result = self._execute_task(context, task_orig)
             ^^^^^^^^^^^^^^^^^^^^^^^^^^^^^^^^^^^^^^
  File "/home/airflow/.local/lib/python3.12/site-packages/airflow/models/taskinstance.py", line 3183, in _execute_task
    return _execute_task(self, context, task_orig)
           ^^^^^^^^^^^^^^^^^^^^^^^^^^^^^^^^^^^^^^^
  File "/home/airflow/.local/lib/python3.12/site-packages/airflow/models/taskinstance.py", line 767, in _execute_task
    result = _execute_callable(context=context, **execute_callable_kwargs)
             ^^^^^^^^^^^^^^^^^^^^^^^^^^^^^^^^^^^^^^^^^^^^^^^^^^^^^^^^^^^^^
  File "/home/airflow/.local/lib/python3.12/site-packages/airflow/models/taskinstance.py", line 733, in _execute_callable
    return ExecutionCallableRunner(
           ^^^^^^^^^^^^^^^^^^^^^^^^
  File "/home/airflow/.local/lib/python3.12/site-packages/airflow/utils/operator_helpers.py", line 252, in run
    return self.func(*args, **kwargs)
           ^^^^^^^^^^^^^^^^^^^^^^^^^^
  File "/home/airflow/.local/lib/python3.12/site-packages/airflow/models/baseoperator.py", line 422, in wrapper
    return func(self, *args, **kwargs)
           ^^^^^^^^^^^^^^^^^^^^^^^^^^^
  File "/home/airflow/.local/lib/python3.12/site-packages/airflow/operators/python.py", line 238, in execute
    return_value = self.execute_callable()
                   ^^^^^^^^^^^^^^^^^^^^^^^
  File "/home/airflow/.local/lib/python3.12/site-packages/airflow/operators/python.py", line 256, in execute_callable
    return runner.run(*self.op_args, **self.op_kwargs)
           ^^^^^^^^^^^^^^^^^^^^^^^^^^^^^^^^^^^^^^^^^^^
  File "/home/airflow/.local/lib/python3.12/site-packages/airflow/utils/operator_helpers.py", line 252, in run
    return self.func(*args, **kwargs)
           ^^^^^^^^^^^^^^^^^^^^^^^^^^
  File "/opt/airflow/dags/selenium_dag_01.py", line 137, in scrape_data
    driver = webdriver.Chrome(service=service, options=chrome_options)
             ^^^^^^^^^^^^^^^^^^^^^^^^^^^^^^^^^^^^^^^^^^^^^^^^^^^^^^^^^
  File "/home/airflow/.local/lib/python3.12/site-packages/selenium/webdriver/chrome/webdriver.py", line 45, in __init__
    super().__init__(
  File "/home/airflow/.local/lib/python3.12/site-packages/selenium/webdriver/chromium/webdriver.py", line 66, in __init__
    super().__init__(command_executor=executor, options=options)
  File "/home/airflow/.local/lib/python3.12/site-packages/selenium/webdriver/remote/webdriver.py", line 241, in __init__
    self.start_session(capabilities)
  File "/home/airflow/.local/lib/python3.12/site-packages/selenium/webdriver/remote/webdriver.py", line 329, in start_session
    response = self.execute(Command.NEW_SESSION, caps)["value"]
               ^^^^^^^^^^^^^^^^^^^^^^^^^^^^^^^^^^^^^^^
  File "/home/airflow/.local/lib/python3.12/site-packages/selenium/webdriver/remote/webdriver.py", line 384, in execute
    self.error_handler.check_response(response)
  File "/home/airflow/.local/lib/python3.12/site-packages/selenium/webdriver/remote/errorhandler.py", line 232, in check_response
    raise exception_class(message, screen, stacktrace)
selenium.common.exceptions.WebDriverException: Message: unknown error: Chrome failed to start: exited abnormally.
  (unknown error: DevToolsActivePort file doesn't exist)
  (The process started from chrome location /usr/bin/custom-google-chrome is no longer running, so ChromeDriver is assuming that Chrome has crashed.)
Stacktrace:
#0 0x5620b742e4e3 <unknown>
#1 0x5620b715dc76 <unknown>
#2 0x5620b7186d78 <unknown>
#3 0x5620b7183029 <unknown>
#4 0x5620b71c1ccc <unknown>
#5 0x5620b71c147f <unknown>
#6 0x5620b71b8de3 <unknown>
#7 0x5620b718e2dd <unknown>
#8 0x5620b718f34e <unknown>
#9 0x5620b73ee3e4 <unknown>
#10 0x5620b73f23d7 <unknown>
#11 0x5620b73fcb20 <unknown>
#12 0x5620b73f3023 <unknown>
#13 0x5620b73c11aa <unknown>
#14 0x5620b74176b8 <unknown>
#15 0x5620b7417847 <unknown>
#16 0x5620b7427243 <unknown>
#17 0x7f83f819e1c4 <unknown>

[2025-01-05T22:40:56.803+0000] {local_task_job_runner.py:266} INFO - Task exited with return code 1
[2025-01-05T22:40:56.820+0000] {taskinstance.py:3895} INFO - 0 downstream tasks scheduled from follow-on schedule check
[2025-01-05T22:40:56.821+0000] {local_task_job_runner.py:245} INFO - ::endgroup::
